Workbook

Sheet 系統匯入資料
A1: 公式說明：M=ROUND(IF(L<1,(J+K)*L+(J+K),(J+K)*(L/100)+(J+K)),2)；O=ROUND(M*I+N,0)。
A3: 類別 | B3: 狀態 | C3: 型號 | D3: 品名 | E3: 單位 | F3: 產品描述 | G3: 圖片 | H3: 來源幣別 | I3: 匯率 | J3: 來源成本(USD) | K3: 運費(USD) | L3: 關稅/其他成本加成(%) | M3: 加乘後金額(USD) | N3: 其他加購(TWD) | O3: 成本(TWD) | P3: 規劃費 | Q3: 設定費 | R3: 特殊倍數_市場價 | S3: 特殊倍數_市場最低價 | T3: 特殊倍數_設計師價 | U3: 特殊倍數_一級經銷商 | V3: 特殊倍數_二級經銷商 | W3: 特殊倍數_分公司 | X3: 特殊倍數_總經銷商 | Y3: 市場報價 | Z3: 市場最低價 | AA3: 設計師價 | AB3: 一級經銷商 | AC3: 二級經銷商 | AD3: 分公司 | AE3: 總經銷商 | AF3: 市場最低價折扣比例 | AG3: 設計師價折扣比例 | AH3: 一級經銷商折扣比例 | AI3: 二級經銷商折扣比例 | AJ3: 分公司折扣比例 | AK3: 總經銷商折扣比例 | AL3: 備註
A4: (停產) | B4: 一般 | C4: B10W4 | D4: MixSwitch 巴赫四切智慧開關-金 | E4: 顆 | F4: 尺寸：86 x 86 x 38.3 毫米 前面板：塑膠面板，需更換為金屬面板 電源供應器：AC100-240V，50/60Hz 最大限度。負載：800W/路（四路合計小於1200W） | G4: /uploads/product_images/B10W4.png | H4: USD | I4: 32.5 | J4: 52 | K4: =IFERROR(VLOOKUP(C4,[1]智慧家庭產品價格表.含稅!C:S,17,FALSE),0) -> 1 | L4: 13 | M4: =ROUND(IF(L4<1,(J4+K4)*L4+(J4+K4),(J4+K4)*(L4/100)+(J4+K4)),2) -> 59.89 | N4: 20 | O4: =ROUND(M4*I4+N4,0) -> 1966 | P4: 210 | Q4: 315 | R4: 3.771 | S4: 0.941 | T4: 0.952 | U4: 0.952 | V4: 0.952 | W4: 0.952 | X4: 0.952 | Y4: =ROUND(O4*R4,0) -> 7414 | Z4: =ROUND(Y4*S4*AF4,0) -> 5930 | AA4: =ROUND(Y4*T4*AG4,0) -> 5294 | AB4: =ROUND(Y4*U4*AH4,0) -> 3529 | AC4: =ROUND(Y4*V4*AI4,0) -> 4588 | AD4: =ROUND(Y4*W4*AJ4,0) -> 2823 | AE4: =ROUND(Y4*X4*AK4,0) -> 3176 | AF4: 0.85 | AG4: 0.75 | AH4: 0.5 | AI4: 0.65 | AJ4: 0.4 | AK4: 0.45 | AL4: 需提供零線(N)-白線 採用86底盒安裝(智崴提供)
A5: (停產) | B5: 一般 | C5: B10W8 | D5: MixSwitch 巴赫八切智慧開關-金 | E5: 顆 | F5: 尺寸：86 x 86 x 38.3 毫米 前面板：塑膠面板，需更換為金屬面板 電源供應器：AC100-240V，50/60Hz 最大限度。負載：800W/路（四路合計小於1200W） | G5: /uploads/product_images/B10W8.png | H5: USD | I5: 32.5 | J5: 57 | K5: =IFERROR(VLOOKUP(C5,[1]智慧家庭產品價格表.含稅!C:S,17,FALSE),0) -> 1 | L5: 13 | M5: =ROUND(IF(L5<1,(J5+K5)*L5+(J5+K5),(J5+K5)*(L5/100)+(J5+K5)),2) -> 65.54 | N5: 20 | O5: =ROUND(M5*I5+N5,0) -> 2150 | P5: 210 | Q5: 315 | R5: 3.749 | S5: 0.941 | T5: 0.952 | U5: 0.952 | V5: 0.952 | W5: 0.952 | X5: 0.952 | Y5: =ROUND(O5*R5,0) -> 8060 | Z5: =ROUND(Y5*S5*AF5,0) -> 6447 | AA5: =ROUND(Y5*T5*AG5,0) -> 5755 | AB5: =ROUND(Y5*U5*AH5,0) -> 3837 | AC5: =ROUND(Y5*V5*AI5,0) -> 4988 | AD5: =ROUND(Y5*W5*AJ5,0) -> 3069 | AE5: =ROUND(Y5*X5*AK5,0) -> 3453 | AF5: 0.85 | AG5: 0.75 | AH5: 0.5 | AI5: 0.65 | AJ5: 0.4 | AK5: 0.45 | AL5: 需提供零線(N)-白線 採用86底盒安裝(智崴提供)
A6: (停產) | B6: 一般 | C6: CT10W-B1VO | D6: 小方遙控器 | E6: 顆 | F6: 控制電視、空調、投影機等紅外線電器。 支援學習功能。 | G6: /uploads/product_images/CT10W-B1VO.png | H6: USD | I6: 32.5 | J6: 11 | K6: =IFERROR(VLOOKUP(C6,[1]智慧家庭產品價格表.含稅!C:S,17,FALSE),0) -> 1 | L6: 13 | M6: =ROUND(IF(L6<1,(J6+K6)*L6+(J6+K6),(J6+K6)*(L6/100)+(J6+K6)),2) -> 13.56 | N6: 100 | O6: =ROUND(M6*I6+N6,0) -> 541 | P6: 52 | Q6: 315 | R6: 3.513 | S6: 0.941 | T6: 0.952 | U6: 0.952 | V6: 0.952 | W6: 0.952 | X6: 0.952 | Y6: =ROUND(O6*R6,0) -> 1901 | Z6: =ROUND(Y6*S6*AF6,0) -> 1521 | AA6: =ROUND(Y6*T6*AG6,0) -> 1357 | AB6: =ROUND(Y6*U6*AH6,0) -> 905 | AC6: =ROUND(Y6*V6*AI6,0) -> 1176 | AD6: =ROUND(Y6*W6*AJ6,0) -> 724 | AE6: =ROUND(Y6*X6*AK6,0) -> 814 | AF6: 0.85 | AG6: 0.75 | AH6: 0.5 | AI6: 0.65 | AJ6: 0.4 | AK6: 0.45
A7: (停產) | B7: 一般 | C7: DCN08016 | D7: 智慧磁力格柵燈8W 3000k Q系列 | E7: 顆 | F7: 單色溫度燈 具有「智慧調光模組軟光系列」可調光 功率：8英寸12w 尺寸：長220 * 寬103 * H22mm長440 * 寬22 * 高45毫米 發光角度：28° 輸入電壓 48V 材料和顏色：航空鋁和黑色 顯色指數 CRI≧90 控制方式：語音、Mixpad、場景切換、APP | G7: /uploads/product_images/DCN08016.png | H7: USD | I7: 32.5 | J7: 20 | K7: =IFERROR(VLOOKUP(C7,[1]智慧家庭產品價格表.含稅!C:S,17,FALSE),0) -> 1 | L7: 13 | M7: =ROUND(IF(L7<1,(J7+K7)*L7+(J7+K7),(J7+K7)*(L7/100)+(J7+K7)),2) -> 23.73 | N7: 0 | O7: =ROUND(M7*I7+N7,0) -> 771 | P7: 158 | Q7: 315 | R7: 3.439 | S7: 1 | T7: 1.016 | U7: 1.048 | V7: 1.025 | W7: 1.071 | X7: 1.058 | Y7: =ROUND(O7*R7,0) -> 2651 | Z7: =ROUND(Y7*S7*AF7,0) -> 2253 | AA7: =ROUND(Y7*T7*AG7,0) -> 2020 | AB7: =ROUND(Y7*U7*AH7,0) -> 1389 | AC7: =ROUND(Y7*V7*AI7,0) -> 1766 | AD7: =ROUND(Y7*W7*AJ7,0) -> 1136 | AE7: =ROUND(Y7*X7*AK7,0) -> 1262 | AF7: 0.85 | AG7: 0.75 | AH7: 0.5 | AI7: 0.65 | AJ7: 0.4 | AK7: 0.45
A8: (停產) | B8: 一般 | C8: DCN08017 | D8: 智慧磁力泛光燈8W 6000k Q系列 | E8: 顆 | F8: 單色溫度燈 具有「智慧調光模組軟光系列」可調光 色溫：3000k/4000k/6000k 尺寸：長300 * 寬22 * H45 / L600 * 寬22 * 高45mm 發光角度：100° 輸入電壓 48V 材料和顏色：航空鋁和黑色 顯色指數 CRI≧90 控制方式：語音、Mixpad、場景切換、APP | G8: /uploads/product_images/DCN08017.png | H8: USD | I8: 32.5 | J8: 17 | K8: =IFERROR(VLOOKUP(C8,[1]智慧家庭產品價格表.含稅!C:S,17,FALSE),0) -> 1 | L8: 13 | M8: =ROUND(IF(L8<1,(J8+K8)*L8+(J8+K8),(J8+K8)*(L8/100)+(J8+K8)),2) -> 20.34 | N8: 0 | O8: =ROUND(M8*I8+N8,0) -> 661 | P8: 158 | Q8: 315 | R8: 3.312 | S8: 1 | T8: 1.016 | U8: 1.047 | V8: 1.025 | W8: 1.071 | X8: 1.058 | Y8: =ROUND(O8*R8,0) -> 2189 | Z8: =ROUND(Y8*S8*AF8,0) -> 1861 | AA8: =ROUND(Y8*T8*AG8,0) -> 1668 | AB8: =ROUND(Y8*U8*AH8,0) -> 1146 | AC8: =ROUND(Y8*V8*AI8,0) -> 1458 | AD8: =ROUND(Y8*W8*AJ8,0) -> 938 | AE8: =ROUND(Y8*X8*AK8,0) -> 1042 | AF8: 0.85 | AG8: 0.75 | AH8: 0.5 | AI8: 0.65 | AJ8: 0.4 | AK8: 0.45
A9: (停產) | B9: 一般 | C9: DCN08018 | D9: 智慧磁力射燈8W 4000k Q系列 | E9: 顆 | F9: 單色溫度燈 具有「智慧調光模組軟光系列」可調光 尺寸Φ45毫米*105毫米 發光角度：28° 輸入電壓 48V 材料和顏色：航空鋁和黑色 顯色指數 CRI≧90 控制方式：語音、Mixpad、場景切換、APP | G9: /uploads/product_images/DCN08018.png | H9: USD | I9: 32.5 | J9: 20 | K9: =IFERROR(VLOOKUP(C9,[1]智慧家庭產品價格表.含稅!C:S,17,FALSE),0) -> 1 | L9: 13 | M9: =ROUND(IF(L9<1,(J9+K9)*L9+(J9+K9),(J9+K9)*(L9/100)+(J9+K9)),2) -> 23.73 | N9: 0 | O9: =ROUND(M9*I9+N9,0) -> 771 | P9: 158 | Q9: 315 | R9: 3.445 | S9: 1 | T9: 1.016 | U9: 1.047 | V9: 1.026 | W9: 1.071 | X9: 1.058 | Y9: =ROUND(O9*R9,0) -> 2656 | Z9: =ROUND(Y9*S9*AF9,0) -> 2258 | AA9: =ROUND(Y9*T9*AG9,0) -> 2024 | AB9: =ROUND(Y9*U9*AH9,0) -> 1390 | AC9: =ROUND(Y9*V9*AI9,0) -> 1771 | AD9: =ROUND(Y9*W9*AJ9,0) -> 1138 | AE9: =ROUND(Y9*X9*AK9,0) -> 1265 | AF9: 0.85 | AG9: 0.75 | AH9: 0.5 | AI9: 0.65 | AJ9: 0.4 | AK9: 0.45
A10: (停產) | B10: 一般 | C10: DCN08021 | D10: 智慧磁力格柵燈8W 4000k Q系列 | E10: 顆 | F10: 單色溫度燈 具有「智慧調光模組軟光系列」可調光 功率：8英寸12w 尺寸：長220 * 寬103 * H22mm長440 * 寬22 * 高45毫米 發光角度：28° 輸入電壓 48V 材料和顏色：航空鋁和黑色 顯色指數 CRI≧90 控制方式：語音、Mixpad、場景切換、APP | G10: /uploads/product_images/DCN08021.png | H10: USD | I10: 32.5 | J10: 20 | K10: =IFERROR(VLOOKUP(C10,[1]智慧家庭產品價格表.含稅!C:S,17,FALSE),0) -> 1 | L10: 13 | M10: =ROUND(IF(L10<1,(J10+K10)*L10+(J10+K10),(J10+K10)*(L10/100)+(J10+K10)),2) -> 23.73 | N10: 0 | O10: =ROUND(M10*I10+N10,0) -> 771 | P10: 158 | Q10: 315 | R10: 3.439 | S10: 1 | T10: 1.016 | U10: 1.048 | V10: 1.025 | W10: 1.071 | X10: 1.058 | Y10: =ROUND(O10*R10,0) -> 2651 | Z10: =ROUND(Y10*S10*AF10,0) -> 2253 | AA10: =ROUND(Y10*T10*AG10,0) -> 2020 | AB10: =ROUND(Y10*U10*AH10,0) -> 1389 | AC10: =ROUND(Y10*V10*AI10,0) -> 1766 | AD10: =ROUND(Y10*W10*AJ10,0) -> 1136 | AE10: =ROUND(Y10*X10*AK10,0) -> 1262 | AF10: 0.85 | AG10: 0.75 | AH10: 0.5 | AI10: 0.65 | AJ10: 0.4 | AK10: 0.45
A11: (停產) | B11: 一般 | C11: DCN08025 | D11: 智慧磁力格柵燈8W 6000k Q系列 | E11: 顆 | F11: 單色溫度燈 具有「智慧調光模組軟光系列」可調光 功率：8英寸12w 尺寸：長220 * 寬103 * H22mm長440 * 寬22 * 高45毫米 發光角度：28° 輸入電壓 48V 材料和顏色：航空鋁和黑色 顯色指數 CRI≧90 控制方式：語音、Mixpad、場景切換、APP | G11: /uploads/product_images/DCN08025.png | H11: USD | I11: 32.5 | J11: 22.1 | K11: =IFERROR(VLOOKUP(C11,[1]智慧家庭產品價格表.含稅!C:S,17,FALSE),0) -> 1 | L11: 13 | M11: =ROUND(IF(L11<1,(J11+K11)*L11+(J11+K11),(J11+K11)*(L11/100)+(J11+K11)),2) -> 26.1 | N11: 0 | O11: =ROUND(M11*I11+N11,0) -> 848 | P11: 158 | Q11: 315 | R11: 3.127 | S11: 1 | T11: 1.016 | U11: 1.048 | V11: 1.025 | W11: 1.071 | X11: 1.058 | Y11: =ROUND(O11*R11,0) -> 2652 | Z11: =ROUND(Y11*S11*AF11,0) -> 2254 | AA11: =ROUND(Y11*T11*AG11,0) -> 2021 | AB11: =ROUND(Y11*U11*AH11,0) -> 1390 | AC11: =ROUND(Y11*V11*AI11,0) -> 1767 | AD11: =ROUND(Y11*W11*AJ11,0) -> 1136 | AE11: =ROUND(Y11*X11*AK11,0) -> 1263 | AF11: 0.85 | AG11: 0.75 | AH11: 0.5 | AI11: 0.65 | AJ11: 0.4 | AK11: 0.45
A12: (停產) | B12: 一般 | C12: DCN08027 | D12: 智慧磁力射燈8W 6000k Q系列 | E12: 顆 | F12: 單色溫度燈 具有「智慧調光模組軟光系列」可調光 尺寸Φ45毫米*105毫米 發光角度：28° 輸入電壓 48V 材料和顏色：航空鋁和黑色 顯色指數 CRI≧90 控制方式：語音、Mixpad、場景切換、APP | G12: /uploads/product_images/DCN08027.png | H12: USD | I12: 32.5 | J12: 21.9 | K12: =IFERROR(VLOOKUP(C12,[1]智慧家庭產品價格表.含稅!C:S,17,FALSE),0) -> 1 | L12: 13 | M12: =ROUND(IF(L12<1,(J12+K12)*L12+(J12+K12),(J12+K12)*(L12/100)+(J12+K12)),2) -> 25.88 | N12: 0 | O12: =ROUND(M12*I12+N12,0) -> 841 | P12: 158 | Q12: 315 | R12: 3.159 | S12: 1 | T12: 1.016 | U12: 1.047 | V12: 1.026 | W12: 1.071 | X12: 1.058 | Y12: =ROUND(O12*R12,0) -> 2657 | Z12: =ROUND(Y12*S12*AF12,0) -> 2258 | AA12: =ROUND(Y12*T12*AG12,0) -> 2025 | AB12: =ROUND(Y12*U12*AH12,0) -> 1391 | AC12: =ROUND(Y12*V12*AI12,0) -> 1772 | AD12: =ROUND(Y12*W12*AJ12,0) -> 1138 | AE12: =ROUND(Y12*X12*AK12,0) -> 1265 | AF12: 0.85 | AG12: 0.75 | AH12: 0.5 | AI12: 0.65 | AJ12: 0.4 | AK12: 0.45
A13: (停產) | B13: 一般 | C13: DCN12019 | D13: 智慧磁性摺疊格柵燈12W 4000k Q系列 | E13: 顆 | F13: 單色溫度燈 具有「智慧調光模組軟光系列」可調光 色溫：3000k/4000k/6000k 尺寸：長220 * 寬103 * H22mm 發光角度：28° 輸入電壓 48V 材料和顏色：航空鋁和黑色 顯色指數 CRI≧90 控制方式：語音、Mixpad、場景切換、APP | G13: /uploads/product_images/DCN12019.jpeg | H13: USD | I13: 32.5 | J13: 29 | K13: =IFERROR(VLOOKUP(C13,[1]智慧家庭產品價格表.含稅!C:S,17,FALSE),0) -> 1 | L13: 13 | M13: =ROUND(IF(L13<1,(J13+K13)*L13+(J13+K13),(J13+K13)*(L13/100)+(J13+K13)),2) -> 33.9 | N13: 0 | O13: =ROUND(M13*I13+N13,0) -> 1102 | P13: 158 | Q13: 315 | R13: 3.391 | S13: 1 | T13: 1.015 | U13: 1.047 | V13: 1.026 | W13: 1.071 | X13: 1.058 | Y13: =ROUND(O13*R13,0) -> 3737 | Z13: =ROUND(Y13*S13*AF13,0) -> 3176 | AA13: =ROUND(Y13*T13*AG13,0) -> 2845 | AB13: =ROUND(Y13*U13*AH13,0) -> 1956 | AC13: =ROUND(Y13*V13*AI13,0) -> 2492 | AD13: =ROUND(Y13*W13*AJ13,0) -> 1601 | AE13: =ROUND(Y13*X13*AK13,0) -> 1779 | AF13: 0.85 | AG13: 0.75 | AH13: 0.5 | AI13: 0.65 | AJ13: 0.4 | AK13: 0.45
A14: (停產) | B14: 一般 | C14: DCN12028 | D14: 智慧磁性摺疊格柵燈12W 6000k Q系列 | E14: 顆 | F14: 單色溫度燈 具有「智慧調光模組軟光系列」可調光 色溫：3000k/4000k/6000k 尺寸：長220 * 寬103 * H22mm 發光角度：28° 輸入電壓 48V 材料和顏色：航空鋁和黑色 顯色指數 CRI≧90 控制方式：語音、Mixpad、場景切換、APP | G14: /uploads/product_images/DCN12028.jpeg | H14: TWD | I14: 32.5 | J14: 0 | K14: =IFERROR(VLOOKUP(C14,[1]智慧家庭產品價格表.含稅!C:S,17,FALSE),0) -> 1 | L14: 13 | M14: =ROUND(IF(L14<1,(J14+K14)*L14+(J14+K14),(J14+K14)*(L14/100)+(J14+K14)),2) -> 1.13 | N14: 0 | O14: =ROUND(M14*I14+N14,0) -> 37 | P14: 158 | Q14: 315 | R14: 100.973 | S14: 1 | T14: 1.016 | U14: 1.048 | V14: 1.026 | W14: 1.071 | X14: 1.058 | Y14: =ROUND(O14*R14,0) -> 3736 | Z14: =ROUND(Y14*S14*AF14,0) -> 3176 | AA14: =ROUND(Y14*T14*AG14,0) -> 2847 | AB14: =ROUND(Y14*U14*AH14,0) -> 1958 | AC14: =ROUND(Y14*V14*AI14,0) -> 2492 | AD14: =ROUND(Y14*W14*AJ14,0) -> 1601 | AE14: =ROUND(Y14*X14*AK14,0) -> 1779 | AF14: 0.85 | AG14: 0.75 | AH14: 0.5 | AI14: 0.65 | AJ14: 0.4 | AK14: 0.45
A15: (停產) | B15: 一般 | C15: DCN15016 | D15: 智慧磁力格柵燈15W 4000k Q系列 | E15: 顆 | F15: 單色溫度燈 具有「智慧調光模組軟光系列」可調光 功率：8英寸12w 尺寸：長220 * 寬103 * H22mm長440 * 寬22 * 高45毫米 發光角度：28° 輸入電壓 48V 材料和顏色：航空鋁和黑色 顯色指數 CRI≧90 控制方式：語音、Mixpad、場景切換、APP | G15: /uploads/product_images/DCN15016.png | H15: USD | I15: 32.5 | J15: 27 | K15: =IFERROR(VLOOKUP(C15,[1]智慧家庭產品價格表.含稅!C:S,17,FALSE),0) -> 1 | L15: 13 | M15: =ROUND(IF(L15<1,(J15+K15)*L15+(J15+K15),(J15+K15)*(L15/100)+(J15+K15)),2) -> 31.64 | N15: 0 | O15: =ROUND(M15*I15+N15,0) -> 1028 | P15: 158 | Q15: 315 | R15: 3.37 | S15: 1 | T15: 1.016 | U15: 1.048 | V15: 1.025 | W15: 1.072 | X15: 1.058 | Y15: =ROUND(O15*R15,0) -> 3464 | Z15: =ROUND(Y15*S15*AF15,0) -> 2944 | AA15: =ROUND(Y15*T15*AG15,0) -> 2640 | AB15: =ROUND(Y15*U15*AH15,0) -> 1815 | AC15: =ROUND(Y15*V15*AI15,0) -> 2308 | AD15: =ROUND(Y15*W15*AJ15,0) -> 1485 | AE15: =ROUND(Y15*X15*AK15,0) -> 1649 | AF15: 0.85 | AG15: 0.75 | AH15: 0.5 | AI15: 0.65 | AJ15: 0.4 | AK15: 0.45
A16: (停產) | B16: 一般 | C16: DCN15017 | D16: 智慧磁性泛光燈15W 4000k Q系列 | E16: 顆 | F16: 單色溫度燈 具有「智慧調光模組軟光系列」可調光 功率：8w 15w 尺寸：長300 * 寬22 * H45 / L600 * 寬22 * 高45mm 發光角度：100° 輸入電壓 48V 材料和顏色：航空鋁和黑色 顯色指數 CRI≧90 控制方式：語音、Mixpad、場景切換、APP | G16: /uploads/product_images/DCN15017.png | H16: USD | I16: 32.5 | J16: 23 | K16: =IFERROR(VLOOKUP(C16,[1]智慧家庭產品價格表.含稅!C:S,17,FALSE),0) -> 1 | L16: 13 | M16: =ROUND(IF(L16<1,(J16+K16)*L16+(J16+K16),(J16+K16)*(L16/100)+(J16+K16)),2) -> 27.12 | N16: 0 | O16: =ROUND(M16*I16+N16,0) -> 881 | P16: 158 | Q16: 315 | R16: 3.38 | S16: 1 | T16: 1.016 | U16: 1.047 | V16: 1.026 | W16: 1.071 | X16: 1.058 | Y16: =ROUND(O16*R16,0) -> 2978 | Z16: =ROUND(Y16*S16*AF16,0) -> 2531 | AA16: =ROUND(Y16*T16*AG16,0) -> 2269 | AB16: =ROUND(Y16*U16*AH16,0) -> 1559 | AC16: =ROUND(Y16*V16*AI16,0) -> 1986 | AD16: =ROUND(Y16*W16*AJ16,0) -> 1276 | AE16: =ROUND(Y16*X16*AK16,0) -> 1418 | AF16: 0.85 | AG16: 0.75 | AH16: 0.5 | AI16: 0.65 | AJ16: 0.4 | AK16: 0.45
A17: (停產) | B17: 一般 | C17: DCN15025 | D17: 智慧磁格柵燈15W 6000k Q系列 | E17: 顆 | F17: 單色溫度燈 具有「智慧調光模組軟光系列」可調光 功率：8英寸12w 尺寸：長220 * 寬103 * H22mm長440 * 寬22 * 高45毫米 發光角度：28° 輸入電壓 48V 材料和顏色：航空鋁和黑色 顯色指數 CRI≧90 控制方式：語音、Mixpad、場景切換、APP | G17: /uploads/product_images/DCN15025.png | H17: USD | I17: 32.5 | J17: 29.52 | K17: =IFERROR(VLOOKUP(C17,[1]智慧家庭產品價格表.含稅!C:S,17,FALSE),0) -> 1 | L17: 13 | M17: =ROUND(IF(L17<1,(J17+K17)*L17+(J17+K17),(J17+K17)*(L17/100)+(J17+K17)),2) -> 34.49 | N17: 0 | O17: =ROUND(M17*I17+N17,0) -> 1121 | P17: 158 | Q17: 315 | R17: 3.091 | S17: 1 | T17: 1.015 | U17: 1.048 | V17: 1.025 | W17: 1.071 | X17: 1.058 | Y17: =ROUND(O17*R17,0) -> 3465 | Z17: =ROUND(Y17*S17*AF17,0) -> 2945 | AA17: =ROUND(Y17*T17*AG17,0) -> 2638 | AB17: =ROUND(Y17*U17*AH17,0) -> 1816 | AC17: =ROUND(Y17*V17*AI17,0) -> 2309 | AD17: =ROUND(Y17*W17*AJ17,0) -> 1484 | AE17: =ROUND(Y17*X17*AK17,0) -> 1650 | AF17: 0.85 | AG17: 0.75 | AH17: 0.5 | AI17: 0.65 | AJ17: 0.4 | AK17: 0.45
... A22: (停產) | B22: 一般 | C22: DLW38074 | D22: HDMI氛圍燈帶（120Hz） | E22: 組 | F22: 電源：交流100-240V～50/60Hz 規格：3.06m/條，共2條 功率：38W（LED：144顆/條） 適配器電纜長度：1.5m 支援最高刷新率：1920x1080P@120Hz 顏色：RGB 相容螢幕尺寸<90吋且解析度>720P的電視或顯示器 | G22: /uploads/product_images/DLW38074.png | H22: USD | I22: 32.5 | J22: 143 | K22: =IFERROR(VLOOKUP(C22,[1]智慧家庭產品價格表.含稅!C:S,17,FALSE),0) -> 1 | L22: 13 | M22: =ROUND(IF(L22<1,(J22+K22)*L22+(J22+K22),(J22+K22)*(L22/100)+(J22+K22)),2) -> 162.72 | N22: 0 | O22: =ROUND(M22*I22+N22,0) -> 5288 | P22: 525 | Q22: 525 | R22: 3.584 | S22: 0.941 | T22: 0.952 | U22: 0.952 | V22: 0.952 | W22: 0.952 | X22: 0.952 | Y22: =ROUND(O22*R22,0) -> 18952 | Z22: =ROUND(Y22*S22*AF22,0) -> 15159 | AA22: =ROUND(Y22*T22*AG22,0) -> 13532 | AB22: =ROUND(Y22*U22*AH22,0) -> 9021 | AC22: =ROUND(Y22*V22*AI22,0) -> 11727 | AD22: =ROUND(Y22*W22*AJ22,0) -> 7217 | AE22: =ROUND(Y22*X22*AK22,0) -> 8119 | AF22: 0.85 | AG22: 0.75 | AH22: 0.5 | AI22: 0.65 | AJ22: 0.4 | AK22: 0.45
A23: (停產) | B23: 一般 | C23: DLW48326 | D23: 蒼芎智慧燈條(5M) | E23: 組 | F23: LED燈帶尺寸：L5000mm * W14mm * H4mm 功率：DC24V 光束角度：120° 額定功率：8W/m CRI>90Ra 調光：1-100% 光通量：>800lm/m 顏色：RGB 1600萬色色溫範圍： 2700K-6000K 工作溫度：0℃ - 40℃ | G23: /uploads/product_images/DLW48326.png | H23: USD | I23: 32.5 | J23: 54 | K23: =IFERROR(VLOOKUP(C23,[1]智慧家庭產品價格表.含稅!C:S,17,FALSE),0) -> 6 | L23: 13 | M23: =ROUND(IF(L23<1,(J23+K23)*L23+(J23+K23),(J23+K23)*(L23/100)+(J23+K23)),2) -> 67.8 | N23: 75 | O23: =ROUND(M23*I23+N23,0) -> 2279 | P23: 210 | Q23: 525 | R23: 2.104 | S23: 1.176 | T23: 1.206 | U23: 1.333 | V23: 1.245 | W23: 1.428 | X23: 1.375 | Y23: =ROUND(O23*R23,0) -> 4795 | Z23: =ROUND(Y23*S23*AF23,0) -> 4793 | AA23: =ROUND(Y23*T23*AG23,0) -> 4337 | AB23: =ROUND(Y23*U23*AH23,0) -> 3196 | AC23: =ROUND(Y23*V23*AI23,0) -> 3880 | AD23: =ROUND(Y23*W23*AJ23,0) -> 2739 | AE23: =ROUND(Y23*X23*AK23,0) -> 2967 | AF23: 0.85 | AG23: 0.75 | AH23: 0.5 | AI23: 0.65 | AJ23: 0.4 | AK23: 0.45 | AL23: 需提拱110V插座
A24: (停產) | B24: 一般 | C24: DSZ07049 | D24: SOPRO 投射燈-方形-7W24° | E24: 顆 | F24: 開孔尺寸：55*55mm 尺寸：長67*寬67*高81mm 表面：黑色、白色 顯色指數（CRI）：Ra>95 統一眩光等級（UGR）：UGR<9 光束角度：24° 功率：7W 光通量：>350lm 色溫範圍：2700K~6000K 調光：PWM數位調光 調光頻率：3.84kHz | G24: /uploads/product_images/DSZ07049.png | H24: USD | I24: 32.5 | J24: 30.46 | K24: =IFERROR(VLOOKUP(C24,[1]智慧家庭產品價格表.含稅!C:S,17,FALSE),0) -> 1 | L24: 13 | M24: =ROUND(IF(L24<1,(J24+K24)*L24+(J24+K24),(J24+K24)*(L24/100)+(J24+K24)),2) -> 35.55 | N24: 20 | O24: =ROUND(M24*I24+N24,0) -> 1175 | P24: 158 | Q24: 315 | R24: 3.709 | S24: 0.941 | T24: 0.952 | U24: 0.952 | V24: 0.952 | W24: 0.952 | X24: 0.952 | Y24: =ROUND(O24*R24,0) -> 4358 | Z24: =ROUND(Y24*S24*AF24,0) -> 3486 | AA24: =ROUND(Y24*T24*AG24,0) -> 3112 | AB24: =ROUND(Y24*U24*AH24,0) -> 2074 | AC24: =ROUND(Y24*V24*AI24,0) -> 2697 | AD24: =ROUND(Y24*W24*AJ24,0) -> 1660 | AE24: =ROUND(Y24*X24*AK24,0) -> 1867 | AF24: 0.85 | AG24: 0.75 | AH24: 0.5 | AI24: 0.65 | AJ24: 0.4 | AK24: 0.45 | AL24: 開孔尺寸55*55mm
A25: (停產) | B25: 一般 | C25: DSZ07050 | D25: SOPRO 投射燈-方形-7W36° | E25: 顆 | F25: 開孔尺寸：55*55mm 尺寸：長67*寬67*高81mm 表面：黑色、白色 顯色指數（CRI）：Ra>95 統一眩光等級（UGR）：UGR<9 光束角度：36° 功率：7W 光通量：>350lm 色溫範圍：2700K~6000K 調光：PWM數位調光 調光頻率：3.84kHz | G25: /uploads/product_images/DSZ07050.png | H25: USD | I25: 32.5 | J25: 30.46 | K25: =IFERROR(VLOOKUP(C25,[1]智慧家庭產品價格表.含稅!C:S,17,FALSE),0) -> 1 | L25: 13 | M25: =ROUND(IF(L25<1,(J25+K25)*L25+(J25+K25),(J25+K25)*(L25/100)+(J25+K25)),2) -> 35.55 | N25: 20 | O25: =ROUND(M25*I25+N25,0) -> 1175 | P25: 158 | Q25: 315 | R25: 3.709 | S25: 0.941 | T25: 0.952 | U25: 0.952 | V25: 0.952 | W25: 0.952 | X25: 0.952 | Y25: =ROUND(O25*R25,0) -> 4358 | Z25: =ROUND(Y25*S25*AF25,0) -> 3486 | AA25: =ROUND(Y25*T25*AG25,0) -> 3112 | AB25: =ROUND(Y25*U25*AH25,0) -> 2074 | AC25: =ROUND(Y25*V25*AI25,0) -> 2697 | AD25: =ROUND(Y25*W25*AJ25,0) -> 1660 | AE25: =ROUND(Y25*X25*AK25,0) -> 1867 | AF25: 0.85 | AG25: 0.75 | AH25: 0.5 | AI25: 0.65 | AJ25: 0.4 | AK25: 0.45 | AL25: 開孔尺寸55*55mm
A26: (停產) | B26: 一般 | C26: DSZ07053 | D26: SOPRO 投射燈-方形-7W15° | E26: 顆 | F26: 開孔尺寸：55*55mm 尺寸：長67*寬67*高81mm 表面：黑色、白色 顯色指數（CRI）：Ra>95 統一眩光等級（UGR）：UGR<9 光束角度：15° 功率：7W 光通量：>350lm 色溫範圍：2700K~6000K 調光：PWM數位調光 調光頻率：3.84kHz | G26: /uploads/product_images/DSZ07053.png | H26: USD | I26: 32.5 | J26: 30.46 | K26: =IFERROR(VLOOKUP(C26,[1]智慧家庭產品價格表.含稅!C:S,17,FALSE),0) -> 1 | L26: 13 | M26: =ROUND(IF(L26<1,(J26+K26)*L26+(J26+K26),(J26+K26)*(L26/100)+(J26+K26)),2) -> 35.55 | N26: 20 | O26: =ROUND(M26*I26+N26,0) -> 1175 | P26: 158 | Q26: 315 | R26: 3.705 | S26: 0.941 | T26: 0.953 | U26: 0.952 | V26: 0.952 | W26: 0.952 | X26: 0.952 | Y26: =ROUND(O26*R26,0) -> 4353 | Z26: =ROUND(Y26*S26*AF26,0) -> 3482 | AA26: =ROUND(Y26*T26*AG26,0) -> 3111 | AB26: =ROUND(Y26*U26*AH26,0) -> 2072 | AC26: =ROUND(Y26*V26*AI26,0) -> 2694 | AD26: =ROUND(Y26*W26*AJ26,0) -> 1658 | AE26: =ROUND(Y26*X26*AK26,0) -> 1865 | AF26: 0.85 | AG26: 0.75 | AH26: 0.5 | AI26: 0.65 | AJ26: 0.4 | AK26: 0.45 | AL26: 開孔尺寸55*55mm
A27: (停產) | B27: 一般 | C27: DSZ07063 | D27: SOPRO 投射燈-方形-7W24°(無框) | E27: 顆 | F27: 開孔尺寸：55*55mm 尺寸：長78*寬78*高81mm 表面：黑色、白色 顯色指數（CRI）：Ra>95 統一眩光等級（UGR）：UGR<9 光束角度：24° 功率：7W 光通量：>350lm 色溫範圍：2700K~6000K 調光：PWM數位調光 調光頻率：3.84kHz | G27: /uploads/product_images/DSZ07063.png | H27: USD | I27: 32.5 | J27: 30.46 | K27: =IFERROR(VLOOKUP(C27,[1]智慧家庭產品價格表.含稅!C:S,17,FALSE),0) -> 1 | L27: 13 | M27: =ROUND(IF(L27<1,(J27+K27)*L27+(J27+K27),(J27+K27)*(L27/100)+(J27+K27)),2) -> 35.55 | N27: 20 | O27: =ROUND(M27*I27+N27,0) -> 1175 | P27: 158 | Q27: 315 | R27: 3.722 | S27: 0.941 | T27: 0.952 | U27: 0.952 | V27: 0.952 | W27: 0.952 | X27: 0.952 | Y27: =ROUND(O27*R27,0) -> 4373 | Z27: =ROUND(Y27*S27*AF27,0) -> 3498 | AA27: =ROUND(Y27*T27*AG27,0) -> 3122 | AB27: =ROUND(Y27*U27*AH27,0) -> 2082 | AC27: =ROUND(Y27*V27*AI27,0) -> 2706 | AD27: =ROUND(Y27*W27*AJ27,0) -> 1665 | AE27: =ROUND(Y27*X27*AK27,0) -> 1873 | AF27: 0.85 | AG27: 0.75 | AH27: 0.5 | AI27: 0.65 | AJ27: 0.4 | AK27: 0.45 | AL27: 開孔尺寸55*55mm
A28: (停產) | B28: 一般 | C28: DSZ07064 | D28: SOPRO 投射燈-方形-7W36°(無框) | E28: 顆 | F28: 開孔尺寸：55*55mm 尺寸：長78*寬78*高81mm 表面：黑色、白色 顯色指數（CRI）：Ra>95 統一眩光等級（UGR）：UGR<9 光束角度：36° 功率：7W 光通量：>350lm 色溫範圍：2700K~6000K 調光：PWM數位調光 調光頻率：3.84kHz | G28: /uploads/product_images/DSZ07064.png | H28: USD | I28: 32.5 | J28: 30.46 | K28: =IFERROR(VLOOKUP(C28,[1]智慧家庭產品價格表.含稅!C:S,17,FALSE),0) -> 1 | L28: 13 | M28: =ROUND(IF(L28<1,(J28+K28)*L28+(J28+K28),(J28+K28)*(L28/100)+(J28+K28)),2) -> 35.55 | N28: 20 | O28: =ROUND(M28*I28+N28,0) -> 1175 | P28: 158 | Q28: 315 | R28: 3.705 | S28: 0.941 | T28: 0.953 | U28: 0.952 | V28: 0.952 | W28: 0.952 | X28: 0.952 | Y28: =ROUND(O28*R28,0) -> 4353 | Z28: =ROUND(Y28*S28*AF28,0) -> 3482 | AA28: =ROUND(Y28*T28*AG28,0) -> 3111 | AB28: =ROUND(Y28*U28*AH28,0) -> 2072 | AC28: =ROUND(Y28*V28*AI28,0) -> 2694 | AD28: =ROUND(Y28*W28*AJ28,0) -> 1658 | AE28: =ROUND(Y28*X28*AK28,0) -> 1865 | AF28: 0.85 | AG28: 0.75 | AH28: 0.5 | AI28: 0.65 | AJ28: 0.4 | AK28: 0.45 | AL28: 開孔尺寸55*55mm
A29: (停產) | B29: 一般 | C29: DSZ07065 | D29: SOPRO 投射燈-方形-7W15°(無框) | E29: 顆 | F29: 開孔尺寸：55*55mm 尺寸：長78*寬78*高81mm 表面：黑色、白色 顯色指數（CRI）：Ra>95 統一眩光等級（UGR）：UGR<9 光束角度：15° 功率：7W 光通量：>350lm 色溫範圍：2700K~6000K 調光：PWM數位調光 調光頻率：3.84kHz | G29: /uploads/product_images/DSZ07065.png | H29: USD | I29: 32.5 | J29: 30.46 | K29: =IFERROR(VLOOKUP(C29,[1]智慧家庭產品價格表.含稅!C:S,17,FALSE),0) -> 1 | L29: 13 | M29: =ROUND(IF(L29<1,(J29+K29)*L29+(J29+K29),(J29+K29)*(L29/100)+(J29+K29)),2) -> 35.55 | N29: 20 | O29: =ROUND(M29*I29+N29,0) -> 1175 | P29: 158 | Q29: 315 | R29: 3.566 | S29: 0.941 | T29: 0.952 | U29: 0.952 | V29: 0.952 | W29: 0.952 | X29: 0.952 | Y29: =ROUND(O29*R29,0) -> 4190 | Z29: =ROUND(Y29*S29*AF29,0) -> 3351 | AA29: =ROUND(Y29*T29*AG29,0) -> 2992 | AB29: =ROUND(Y29*U29*AH29,0) -> 1994 | AC29: =ROUND(Y29*V29*AI29,0) -> 2593 | AD29: =ROUND(Y29*W29*AJ29,0) -> 1596 | AE29: =ROUND(Y29*X29*AK29,0) -> 1795 | AF29: 0.85 | AG29: 0.75 | AH29: 0.5 | AI29: 0.65 | AJ29: 0.4 | AK29: 0.45 | AL29: 開孔尺寸55*55mm
A30: (停產) | B30: 一般 | C30: DSZ07067 | D30: SOPRO 投射燈-圓形-7W15°(無框) | E30: 顆 | F30: 開孔尺寸：φ55mm 尺寸：φ78* H77mm 表面：黑色、白色 顯色指數（CRI）：Ra>95 統一眩光等級（UGR）：UGR<9 光束角度：15° 功率：7W 光通量：>350lm 色溫範圍：2700K~6000K 調光：PWM數位調光 調光頻率：3.84kHz | G30: /uploads/product_images/DSZ07067.png | H30: USD | I30: 32.5 | J30: 30.46 | K30: =IFERROR(VLOOKUP(C30,[1]智慧家庭產品價格表.含稅!C:S,17,FALSE),0) -> 1 | L30: 13 | M30: =ROUND(IF(L30<1,(J30+K30)*L30+(J30+K30),(J30+K30)*(L30/100)+(J30+K30)),2) -> 35.55 | N30: 20 | O30: =ROUND(M30*I30+N30,0) -> 1175 | P30: 158 | Q30: 315 | R30: 3.702 | S30: 0.941 | T30: 0.952 | U30: 0.952 | V30: 0.952 | W30: 0.952 | X30: 0.952 | Y30: =ROUND(O30*R30,0) -> 4350 | Z30: =ROUND(Y30*S30*AF30,0) -> 3479 | AA30: =ROUND(Y30*T30*AG30,0) -> 3106 | AB30: =ROUND(Y30*U30*AH30,0) -> 2071 | AC30: =ROUND(Y30*V30*AI30,0) -> 2692 | AD30: =ROUND(Y30*W30*AJ30,0) -> 1656 | AE30: =ROUND(Y30*X30*AK30,0) -> 1864 | AF30: 0.85 | AG30: 0.75 | AH30: 0.5 | AI30: 0.65 | AJ30: 0.4 | AK30: 0.45 | AL30: 開孔尺寸55mm
A31: (停產) | B31: 一般 | C31: DSZ07069 | D31: SOPRO 投射燈-圓形-7W24°(無框) | E31: 顆 | F31: 開孔尺寸：φ55mm 尺寸：φ78* H77mm 表面：黑色、白色 顯色指數（CRI）：Ra>95 統一眩光等級（UGR）：UGR<9 光束角度：24° 功率：7W 光通量：>350lm 色溫範圍：2700K~6000K 調光：PWM數位調光 調光頻率：3.84kHz | G31: /uploads/product_images/DSZ07069.png | H31: USD | I31: 32.5 | J31: 30.46 | K31: =IFERROR(VLOOKUP(C31,[1]智慧家庭產品價格表.含稅!C:S,17,FALSE),0) -> 1 | L31: 13 | M31: =ROUND(IF(L31<1,(J31+K31)*L31+(J31+K31),(J31+K31)*(L31/100)+(J31+K31)),2) -> 35.55 | N31: 20 | O31: =ROUND(M31*I31+N31,0) -> 1175 | P31: 158 | Q31: 315 | R31: 3.702 | S31: 0.941 | T31: 0.952 | U31: 0.952 | V31: 0.952 | W31: 0.952 | X31: 0.952 | Y31: =ROUND(O31*R31,0) -> 4350 | Z31: =ROUND(Y31*S31*AF31,0) -> 3479 | AA31: =ROUND(Y31*T31*AG31,0) -> 3106 | AB31: =ROUND(Y31*U31*AH31,0) -> 2071 | AC31: =ROUND(Y31*V31*AI31,0) -> 2692 | AD31: =ROUND(Y31*W31*AJ31,0) -> 1656 | AE31: =ROUND(Y31*X31*AK31,0) -> 1864 | AF31: 0.85 | AG31: 0.75 | AH31: 0.5 | AI31: 0.65 | AJ31: 0.4 | AK31: 0.45 | AL31: 開孔尺寸55mm
A32: (停產) | B32: 一般 | C32: DSZ07071 | D32: SOPRO 投射燈-圓形-7W36°(無框) | E32: 顆 | F32: 開孔尺寸：φ55mm 尺寸：φ78* H77mm 表面：黑色、白色 顯色指數（CRI）：Ra>95 統一眩光等級（UGR）：UGR<9 光束角度：36° 功率：7W 光通量：>350lm 色溫範圍：2700K~6000K 調光：PWM數位調光 調光頻率：3.84kHz | G32: /uploads/product_images/DSZ07071.png | H32: USD | I32: 32.5 | J32: 30.46 | K32: =IFERROR(VLOOKUP(C32,[1]智慧家庭產品價格表.含稅!C:S,17,FALSE),0) -> 1 | L32: 13 | M32: =ROUND(IF(L32<1,(J32+K32)*L32+(J32+K32),(J32+K32)*(L32/100)+(J32+K32)),2) -> 35.55 | N32: 20 | O32: =ROUND(M32*I32+N32,0) -> 1175 | P32: 158 | Q32: 315 | R32: 3.702 | S32: 0.941 | T32: 0.952 | U32: 0.952 | V32: 0.952 | W32: 0.952 | X32: 0.952 | Y32: =ROUND(O32*R32,0) -> 4350 | Z32: =ROUND(Y32*S32*AF32,0) -> 3479 | AA32: =ROUND(Y32*T32*AG32,0) -> 3106 | AB32: =ROUND(Y32*U32*AH32,0) -> 2071 | AC32: =ROUND(Y32*V32*AI32,0) -> 2692 | AD32: =ROUND(Y32*W32*AJ32,0) -> 1656 | AE32: =ROUND(Y32*X32*AK32,0) -> 1864 | AF32: 0.85 | AG32: 0.75 | AH32: 0.5 | AI32: 0.65 | AJ32: 0.4 | AK32: 0.45 | AL32: 開孔尺寸55mm
A33: (停產) | B33: 一般 | C33: DSZ12051 | D33: SOPRO 投射燈-方形-12W24° | E33: 顆 | F33: 開孔尺寸：75*75mm 尺寸：長85*寬85*高106mm 表面：黑色、白色 顯色指數（CRI）：Ra>95 統一眩光等級（UGR）：UGR<9 光束角度：24° 功率：12W 光通量：>600lm 色溫範圍：2700K~6000K 調光：PWM數位調光 調光頻率：3.84kHz | G33: /uploads/product_images/DSZ12051.png | H33: USD | I33: 32.5 | J33: 38.92 | K33: =IFERROR(VLOOKUP(C33,[1]智慧家庭產品價格表.含稅!C:S,17,FALSE),0) -> 1 | L33: 13 | M33: =ROUND(IF(L33<1,(J33+K33)*L33+(J33+K33),(J33+K33)*(L33/100)+(J33+K33)),2) -> 45.11 | N33: 20 | O33: =ROUND(M33*I33+N33,0) -> 1486 | P33: 158 | Q33: 315 | R33: 3.68 | S33: 0.941 | T33: 0.952 | U33: 0.952 | V33: 0.952 | W33: 0.952 | X33: 0.952 | Y33: =ROUND(O33*R33,0) -> 5468 | Z33: =ROUND(Y33*S33*AF33,0) -> 4374 | AA33: =ROUND(Y33*T33*AG33,0) -> 3904 | AB33: =ROUND(Y33*U33*AH33,0) -> 2603 | AC33: =ROUND(Y33*V33*AI33,0) -> 3384 | AD33: =ROUND(Y33*W33*AJ33,0) -> 2082 | AE33: =ROUND(Y33*X33*AK33,0) -> 2342 | AF33: 0.85 | AG33: 0.75 | AH33: 0.5 | AI33: 0.65 | AJ33: 0.4 | AK33: 0.45 | AL33: 開孔尺寸75*75mm
A34: (停產) | B34: 一般 | C34: DSZ12052 | D34: SOPRO 投射燈-方形-12W36° | E34: 顆 | F34: 開孔尺寸：75*75mm 尺寸：長85*寬85*高106mm 表面：黑色、白色 顯色指數（CRI）：Ra>95 統一眩光等級（UGR）：UGR<9 光束角度：36° 功率：12W 光通量：>600lm 色溫範圍：2700K~6000K 調光：PWM數位調光 調光頻率：3.84kHz | G34: /uploads/product_images/DSZ12052.png | H34: USD | I34: 32.5 | J34: 38.92 | K34: =IFERROR(VLOOKUP(C34,[1]智慧家庭產品價格表.含稅!C:S,17,FALSE),0) -> 1 | L34: 13 | M34: =ROUND(IF(L34<1,(J34+K34)*L34+(J34+K34),(J34+K34)*(L34/100)+(J34+K34)),2) -> 45.11 | N34: 20 | O34: =ROUND(M34*I34+N34,0) -> 1486 | P34: 158 | Q34: 315 | R34: 3.68 | S34: 0.941 | T34: 0.952 | U34: 0.952 | V34: 0.952 | W34: 0.952 | X34: 0.952 | Y34: =ROUND(O34*R34,0) -> 5468 | Z34: =ROUND(Y34*S34*AF34,0) -> 4374 | AA34: =ROUND(Y34*T34*AG34,0) -> 3904 | AB34: =ROUND(Y34*U34*AH34,0) -> 2603 | AC34: =ROUND(Y34*V34*AI34,0) -> 3384 | AD34: =ROUND(Y34*W34*AJ34,0) -> 2082 | AE34: =ROUND(Y34*X34*AK34,0) -> 2342 | AF34: 0.85 | AG34: 0.75 | AH34: 0.5 | AI34: 0.65 | AJ34: 0.4 | AK34: 0.45 | AL34: 開孔尺寸75*75mm
... A41: (停產) | B41: 一般 | C41: DSZ12072 | D41: SOPRO 投射燈-圓形-12W36°(無框) | E41: 顆 | F41: 開孔尺寸：φ75mm 尺寸：φ100* H106mm 表面：黑色、白色 顯色指數（CRI）：Ra>95 統一眩光等級（UGR）：UGR<9 光束角度：36° 功率：12W 光通量：>600lm 色溫範圍：2700K~6000K 調光：PWM數位調光 調光頻率：3.84kHz | G41: /uploads/product_images/DSZ12072.png | H41: USD | I41: 32.5 | J41: 38.92 | K41: =IFERROR(VLOOKUP(C41,[1]智慧家庭產品價格表.含稅!C:S,17,FALSE),0) -> 1 | L41: 13 | M41: =ROUND(IF(L41<1,(J41+K41)*L41+(J41+K41),(J41+K41)*(L41/100)+(J41+K41)),2) -> 45.11 | N41: 20 | O41: =ROUND(M41*I41+N41,0) -> 1486 | P41: 158 | Q41: 315 | R41: 3.675 | S41: 0.941 | T41: 0.952 | U41: 0.952 | V41: 0.952 | W41: 0.952 | X41: 0.952 | Y41: =ROUND(O41*R41,0) -> 5461 | Z41: =ROUND(Y41*S41*AF41,0) -> 4368 | AA41: =ROUND(Y41*T41*AG41,0) -> 3899 | AB41: =ROUND(Y41*U41*AH41,0) -> 2599 | AC41: =ROUND(Y41*V41*AI41,0) -> 3379 | AD41: =ROUND(Y41*W41*AJ41,0) -> 2080 | AE41: =ROUND(Y41*X41*AK41,0) -> 2339 | AF41: 0.85 | AG41: 0.75 | AH41: 0.5 | AI41: 0.65 | AJ41: 0.4 | AK41: 0.45 | AL41: 開孔尺寸75mm
A42: (停產) | B42: 一般 | C42: DSZ12129 | D42: 蒼芎投射燈 | E42: 顆 | F42: 電源供應器：AC220-240V 50Hz 尺寸：φ85*H103.5mm 開孔尺寸： φ75mm 光束角：36° 額定功率：12W 光通量：>600lm 顯色指數>90Ra 色溫範圍：1800K-20000K RGBCW COB | G42: /uploads/product_images/DSZ12129.png | H42: USD | I42: 32.5 | J42: 53 | K42: =IFERROR(VLOOKUP(C42,[1]智慧家庭產品價格表.含稅!C:S,17,FALSE),0) -> 1 | L42: 13 | M42: =ROUND(IF(L42<1,(J42+K42)*L42+(J42+K42),(J42+K42)*(L42/100)+(J42+K42)),2) -> 61.02 | N42: 0 | O42: =ROUND(M42*I42+N42,0) -> 1983 | P42: 158 | Q42: 315 | R42: 3.414 | S42: 0.941 | T42: 0.952 | U42: 0.952 | V42: 0.952 | W42: 0.952 | X42: 0.952 | Y42: =ROUND(O42*R42,0) -> 6770 | Z42: =ROUND(Y42*S42*AF42,0) -> 5415 | AA42: =ROUND(Y42*T42*AG42,0) -> 4834 | AB42: =ROUND(Y42*U42*AH42,0) -> 3223 | AC42: =ROUND(Y42*V42*AI42,0) -> 4189 | AD42: =ROUND(Y42*W42*AJ42,0) -> 2578 | AE42: =ROUND(Y42*X42*AK42,0) -> 2900 | AF42: 0.85 | AG42: 0.75 | AH42: 0.5 | AI42: 0.65 | AJ42: 0.4 | AK42: 0.45
A43: (停產) | B43: 一般 | C43: DSZ12136 | D43: 蒼芎崁燈 | E43: 顆 | F43: 電源供應器：AC220-240V 50Hz 尺寸：φ85*H95mm 開孔尺寸： φ75mm 光束角：70° 額定功率：12W 光通量：>480lm 顯色指數>90Ra 色溫範圍：1800K-20000K RGBCW COB | G43: /uploads/product_images/DSZ12136.png | H43: USD | I43: 32.5 | J43: 51 | K43: =IFERROR(VLOOKUP(C43,[1]智慧家庭產品價格表.含稅!C:S,17,FALSE),0) -> 1 | L43: 13 | M43: =ROUND(IF(L43<1,(J43+K43)*L43+(J43+K43),(J43+K43)*(L43/100)+(J43+K43)),2) -> 58.76 | N43: 0 | O43: =ROUND(M43*I43+N43,0) -> 1910 | P43: 158 | Q43: 315 | R43: 3.348 | S43: 0.941 | T43: 0.952 | U43: 0.952 | V43: 0.952 | W43: 0.952 | X43: 0.952 | Y43: =ROUND(O43*R43,0) -> 6395 | Z43: =ROUND(Y43*S43*AF43,0) -> 5115 | AA43: =ROUND(Y43*T43*AG43,0) -> 4566 | AB43: =ROUND(Y43*U43*AH43,0) -> 3044 | AC43: =ROUND(Y43*V43*AI43,0) -> 3957 | AD43: =ROUND(Y43*W43*AJ43,0) -> 2435 | AE43: =ROUND(Y43*X43*AK43,0) -> 2740 | AF43: 0.85 | AG43: 0.75 | AH43: 0.5 | AI43: 0.65 | AJ43: 0.4 | AK43: 0.45
A44: (停產) | B44: 一般 | C44: DT40Z07A | D44: 超薄智慧投射燈7W 24°S1 | E44: 顆 | F44: 電源供應器：AC220V，50/60Hz 開孔尺寸：75~85mm 燈尺寸：96mm x 46mm 顯色指數：Ra>90 光束角：24° 光通量：455 lm 功率：7瓦 色溫範圍：2700K~6000K | G44: /uploads/product_images/DT40Z07A.png | H44: USD | I44: 32.5 | J44: 17 | K44: =IFERROR(VLOOKUP(C44,[1]智慧家庭產品價格表.含稅!C:S,17,FALSE),0) -> 1 | L44: 13 | M44: =ROUND(IF(L44<1,(J44+K44)*L44+(J44+K44),(J44+K44)*(L44/100)+(J44+K44)),2) -> 20.34 | N44: 20 | O44: =ROUND(M44*I44+N44,0) -> 681 | P44: 158 | Q44: 315 | R44: 3.172 | S44: 1 | T44: 1.015 | U44: 1.047 | V44: 1.026 | W44: 1.072 | X44: 1.057 | Y44: =ROUND(O44*R44,0) -> 2160 | Z44: =ROUND(Y44*S44*AF44,0) -> 1836 | AA44: =ROUND(Y44*T44*AG44,0) -> 1644 | AB44: =ROUND(Y44*U44*AH44,0) -> 1131 | AC44: =ROUND(Y44*V44*AI44,0) -> 1441 | AD44: =ROUND(Y44*W44*AJ44,0) -> 926 | AE44: =ROUND(Y44*X44*AK44,0) -> 1027 | AF44: 0.85 | AG44: 0.75 | AH44: 0.5 | AI44: 0.65 | AJ44: 0.4 | AK44: 0.45 | AL44: 開孔尺寸80mm
A45: (停產) | B45: 一般 | C45: DT40Z07B | D45: 超薄智慧崁燈7W 105°S1 | E45: 顆 | F45: 電源供應器：AC220V，50/60Hz 開孔尺寸：75~85mm 燈尺寸：96mm x 46mm 顯色指數：Ra>90 光束角：105° 光通量：420 lm 功率：7瓦 色溫範圍：2700K~6000K | G45: /uploads/product_images/DT40Z07B.png | H45: USD | I45: 32.5 | J45: 15 | K45: =IFERROR(VLOOKUP(C45,[1]智慧家庭產品價格表.含稅!C:S,17,FALSE),0) -> 1 | L45: 13 | M45: =ROUND(IF(L45<1,(J45+K45)*L45+(J45+K45),(J45+K45)*(L45/100)+(J45+K45)),2) -> 18.08 | N45: 20 | O45: =ROUND(M45*I45+N45,0) -> 608 | P45: 158 | Q45: 315 | R45: 2.527 | S45: 0.941 | T45: 0.952 | U45: 0.952 | V45: 0.952 | W45: 0.952 | X45: 0.952 | Y45: =ROUND(O45*R45,0) -> 1536 | Z45: =ROUND(Y45*S45*AF45,0) -> 1229 | AA45: =ROUND(Y45*T45*AG45,0) -> 1097 | AB45: =ROUND(Y45*U45*AH45,0) -> 731 | AC45: =ROUND(Y45*V45*AI45,0) -> 950 | AD45: =ROUND(Y45*W45*AJ45,0) -> 585 | AE45: =ROUND(Y45*X45*AK45,0) -> 658 | AF45: 0.85 | AG45: 0.75 | AH45: 0.5 | AI45: 0.65 | AJ45: 0.4 | AK45: 0.45 | AL45: 開孔尺寸80mm
A46: (停產) | B46: 一般 | C46: DXW135148 | D46: 蒼芎吸頂燈PRO | E46: 組 | F46: SKY DOME PRO | G46: /uploads/product_images/DXW135148.png | H46: USD | I46: 32.5 | J46: 1077 | K46: =IFERROR(VLOOKUP(C46,[1]智慧家庭產品價格表.含稅!C:S,17,FALSE),0) -> 1 | L46: 13 | M46: =ROUND(IF(L46<1,(J46+K46)*L46+(J46+K46),(J46+K46)*(L46/100)+(J46+K46)),2) -> 1218.14 | N46: 20 | O46: =ROUND(M46*I46+N46,0) -> 39610 | P46: 315 | Q46: 1575 | R46: 3.591 | S46: 0.941 | T46: 0.952 | U46: 0.952 | V46: 0.952 | W46: 0.952 | X46: 0.952 | Y46: =ROUND(O46*R46,0) -> 142240 | Z46: =ROUND(Y46*S46*AF46,0) -> 113771 | AA46: =ROUND(Y46*T46*AG46,0) -> 101559 | AB46: =ROUND(Y46*U46*AH46,0) -> 67706 | AC46: =ROUND(Y46*V46*AI46,0) -> 88018 | AD46: =ROUND(Y46*W46*AJ46,0) -> 54165 | AE46: =ROUND(Y46*X46*AK46,0) -> 60936 | AF46: 0.85 | AG46: 0.75 | AH46: 0.5 | AI46: 0.65 | AJ46: 0.4 | AK46: 0.45
A47: (停產) | B47: 一般 | C47: DZZ08144 | D47: SOPRO智慧壁燈 | E47: 顆 | F47: 電源供應器：220V-240V～50/60Hz 尺寸：L160mm*W82mm*H104mm 協定：Wi-Fi + BLE 顯色指數：Ra>95 光束角：100° 額定功率：7W 亮度：1% - 100% 光通量：>525Lm 色溫範圍：2700K~6000K | G47: /uploads/product_images/DZZ08144.png | H47: USD | I47: 32.5 | J47: 37 | K47: =IFERROR(VLOOKUP(C47,[1]智慧家庭產品價格表.含稅!C:S,17,FALSE),0) -> 2 | L47: 13 | M47: =ROUND(IF(L47<1,(J47+K47)*L47+(J47+K47),(J47+K47)*(L47/100)+(J47+K47)),2) -> 44.07 | N47: 21 | O47: =ROUND(M47*I47+N47,0) -> 1453 | P47: 315 | Q47: 315 | R47: 2.34 | S47: 1.235 | T47: 1.27 | U47: 1.429 | V47: 1.319 | W47: 1.548 | X47: 1.481 | Y47: =ROUND(O47*R47,0) -> 3400 | Z47: =ROUND(Y47*S47*AF47,0) -> 3569 | AA47: =ROUND(Y47*T47*AG47,0) -> 3239 | AB47: =ROUND(Y47*U47*AH47,0) -> 2429 | AC47: =ROUND(Y47*V47*AI47,0) -> 2915 | AD47: =ROUND(Y47*W47*AJ47,0) -> 2105 | AE47: =ROUND(Y47*X47*AK47,0) -> 2266 | AF47: 0.85 | AG47: 0.75 | AH47: 0.5 | AI47: 0.65 | AJ47: 0.4 | AK47: 0.45
A48: (停產) | B48: 一般 | C48: DZZ16145 | D48: SOPRO智慧落地燈 | E48: 組 | F48: 電源供應器：220V-240V～50/60Hz 尺寸：W250mm*H1560mm 協定：Wi-Fi + BLE 顯色指數：Ra>95 光束角：100° 額定功率：15W 亮度：1% - 100% 光通量：>1050lm 色溫範圍：2700K~6000K | G48: /uploads/product_images/DZZ16145.png | H48: USD | I48: 32.5 | J48: 110 | K48: =IFERROR(VLOOKUP(C48,[1]智慧家庭產品價格表.含稅!C:S,17,FALSE),0) -> 3 | L48: 13 | M48: =ROUND(IF(L48<1,(J48+K48)*L48+(J48+K48),(J48+K48)*(L48/100)+(J48+K48)),2) -> 127.69 | N48: 22 | O48: =ROUND(M48*I48+N48,0) -> 4172 | P48: 158 | Q48: 315 | R48: 0.815 | S48: 2.409 | T48: 2.539 | U48: 3.333 | V48: 2.784 | W48: 3.928 | X48: 3.594 | Y48: =ROUND(O48*R48,0) -> 3400 | Z48: =ROUND(Y48*S48*AF48,0) -> 6962 | AA48: =ROUND(Y48*T48*AG48,0) -> 6474 | AB48: =ROUND(Y48*U48*AH48,0) -> 5666 | AC48: =ROUND(Y48*V48*AI48,0) -> 6153 | AD48: =ROUND(Y48*W48*AJ48,0) -> 5342 | AE48: =ROUND(Y48*X48*AK48,0) -> 5499 | AF48: 0.85 | AG48: 0.75 | AH48: 0.5 | AI48: 0.65 | AJ48: 0.4 | AK48: 0.45
A49: (停產) | B49: 一般 | C49: DZZ45147 | D49: SOPRO智慧吊燈 | E49: 顆 | F49: SOPRO smart dining chandelier | G49: /uploads/product_images/DZZ45147.png | H49: USD | I49: 32.5 | J49: 162 | K49: =IFERROR(VLOOKUP(C49,[1]智慧家庭產品價格表.含稅!C:S,17,FALSE),0) -> 1 | L49: 13 | M49: =ROUND(IF(L49<1,(J49+K49)*L49+(J49+K49),(J49+K49)*(L49/100)+(J49+K49)),2) -> 184.19 | N49: 20 | O49: =ROUND(M49*I49+N49,0) -> 6006 | P49: 315 | Q49: 1575 | R49: 3.629 | S49: 0.941 | T49: 0.952 | U49: 0.952 | V49: 0.952 | W49: 0.952 | X49: 0.952 | Y49: =ROUND(O49*R49,0) -> 21796 | Z49: =ROUND(Y49*S49*AF49,0) -> 17434 | AA49: =ROUND(Y49*T49*AG49,0) -> 15562 | AB49: =ROUND(Y49*U49*AH49,0) -> 10375 | AC49: =ROUND(Y49*V49*AI49,0) -> 13487 | AD49: =ROUND(Y49*W49*AJ49,0) -> 8300 | AE49: =ROUND(Y49*X49*AK49,0) -> 9337 | AF49: 0.85 | AG49: 0.75 | AH49: 0.5 | AI49: 0.65 | AJ49: 0.4 | AK49: 0.45
A50: (停產) | B50: 一般 | C50: GH-Mini | D50: Google語音助理 (WiFi) (恕不挑色) | E50: 台 | G50: /uploads/product_images/GH-Mini.png | H50: USD | I50: 32.5 | J50: 32.76 | K50: =IFERROR(VLOOKUP(C50,[1]智慧家庭產品價格表.含稅!C:S,17,FALSE),0) -> 2 | L50: 13 | M50: =ROUND(IF(L50<1,(J50+K50)*L50+(J50+K50),(J50+K50)*(L50/100)+(J50+K50)),2) -> 39.28 | N50: 0 | O50: =ROUND(M50*I50+N50,0) -> 1277 | P50: 52 | Q50: 315 | R50: 1.449 | S50: 1.176 | T50: 1.079 | U50: 1.619 | V50: 1.245 | W50: 2.024 | X50: 1.799 | Y50: =ROUND(O50*R50,0) -> 1850 | Z50: =ROUND(Y50*S50*AF50,0) -> 1849 | AA50: =ROUND(Y50*T50*AG50,0) -> 1497 | AB50: =ROUND(Y50*U50*AH50,0) -> 1498 | AC50: =ROUND(Y50*V50*AI50,0) -> 1497 | AD50: =ROUND(Y50*W50*AJ50,0) -> 1498 | AE50: =ROUND(Y50*X50*AK50,0) -> 1498 | AF50: 0.85 | AG50: 0.75 | AH50: 0.5 | AI50: 0.65 | AJ50: 0.4 | AK50: 0.45
A51: (停產) | B51: 一般 | C51: MG-A MG-B | D51: 美規面板-白/黑 | E51: 顆 | F51: 美規面板-白/黑 | H51: USD | I51: 32.5 | J51: 2 | K51: =IFERROR(VLOOKUP(C51,[1]智慧家庭產品價格表.含稅!C:S,17,FALSE),0) -> 1 | L51: 13 | M51: =ROUND(IF(L51<1,(J51+K51)*L51+(J51+K51),(J51+K51)*(L51/100)+(J51+K51)),2) -> 3.39 | N51: 20 | O51: =ROUND(M51*I51+N51,0) -> 130 | P51: 52 | Q51: 315 | R51: 1.039 | S51: 1.176 | T51: 1.076 | U51: 1.614 | V51: 1.242 | W51: 2.017 | X51: 1.793 | Y51: =ROUND(O51*R51,0) -> 135 | Z51: =ROUND(Y51*S51*AF51,0) -> 135 | AA51: =ROUND(Y51*T51*AG51,0) -> 109 | AB51: =ROUND(Y51*U51*AH51,0) -> 109 | AC51: =ROUND(Y51*V51*AI51,0) -> 109 | AD51: =ROUND(Y51*W51*AJ51,0) -> 109 | AE51: =ROUND(Y51*X51*AK51,0) -> 109 | AF51: 0.85 | AG51: 0.75 | AH51: 0.5 | AI51: 0.65 | AJ51: 0.4 | AK51: 0.45
...
